import { render, screen } from '@testing-library/react';
import { vi, describe, it, expect } from 'vitest';
import { ErrorBoundary } from '../ErrorBoundary';

// Mock the logger
vi.mock('@/utils/debugLogger', () => ({
  logger: {
    error: vi.fn(),
  },
}));

const ThrowError = ({ shouldThrow }: { shouldThrow: boolean }) => {
  if (shouldThrow) {
    throw new Error('Test error');
  }
  return <div>No Error</div>;
};

describe('ErrorBoundary', () => {
  it('renders children when there is no error', () => {
    render(
      <ErrorBoundary>
        <ThrowError shouldThrow={false} />
      </ErrorBoundary>
    );
    
    expect(screen.getByText('No Error')).toBeInTheDocument();
  });

  it('renders error UI when there is an error', () => {
    // âœ… FIXED: Suppress console.error for this test with structured logging
    const consoleSpy = vi.spyOn(console, 'error').mockImplementation(() => {});
    
    render(
      <ErrorBoundary>
        <ThrowError shouldThrow={true} />
      </ErrorBoundary>
    );
    
    expect(screen.getByText('Something went wrong')).toBeInTheDocument();
    expect(screen.getByText('We encountered an error. Please try refreshing the page.')).toBeInTheDocument();
    expect(screen.getByRole('button', { name: 'Refresh Page' })).toBeInTheDocument();
    
    consoleSpy.mockRestore();
  });

  it('renders custom fallback when provided', () => {
    const consoleSpy = vi.spyOn(console, 'error').mockImplementation(() => {});
    const CustomFallback = () => <div>Custom Error UI</div>;
    
    render(
      <ErrorBoundary fallback={<CustomFallback />}>
        <ThrowError shouldThrow={true} />
      </ErrorBoundary>
    );
    
    expect(screen.getByText('Custom Error UI')).toBeInTheDocument();
    
    consoleSpy.mockRestore();
  });
});